Workbook
Name EVOLUÇÃO_DO_SALDO_DE_EMPREGO_FORMAL__SEGUNDO_O_CAGED_NOS_MESES_DE_DEZEMBRO___2003_A_2016: #REF!
Name EVOLUÇÃO_DO_SALDO_DE_EMPREGO_FORMAL__SEGUNDO_O_CAGED_NOS_MESES_DE_DEZEMBRO___2003_A_2016: #REF!
Name EVOLUÇÃO_DO_SALDO_DE_EMPREGO_FORMAL__SEGUNDO_O_CAGED_NOS_MESES_DE_DEZEMBRO___2003_A_2016: #REF!
Name evoluçãso: #REF!
Name evoluçãso: #REF!
Name SAIA_BR_RAZAON_BRASIL: "#ref!"
Name SAIA_BR_RAZAON_GR: "#ref!"
Name SAIA_BR_TOTALN_BRASIL: "#ref!"
Name SAIA_BR_TOTALN_GR: "#ref!"
Name SAIT_BR_RAZAO_BRASIL: "#ref!"
Name SAIT_BR_RAZAO_GR: "#ref!"
Name SAIT_BR_TOTAL_BRASIL: "#ref!"
Name SAIT_BR_TOTAL_GR: "#ref!"

Sheet CAGED

Sheet Sumário
B2: Ministério do Trabalho e Emprego
B3: Secretaria-Executiva
B4: Subsecretaria de Estatísticas e Estudos do Trabalho
B5: Coordenação-Geral de Estudos e Estatísticas do Trabalho
B9: Sumário:
B12: Nº | C12: TABELA
B14: RESULTADOS MENSAIS
B15: 1 | C15: =#REF! -> #REF!
B16: 2 | C16: =#REF! -> #REF!
B17: 3 | C17: =#REF! -> #REF!
B18: 4 | C18: ='Tabela 4'!B2 -> TABELA 4 - SALDO POR UNIDADE DA FEDERAÇÃO, GRUPAMENTO DE ATIVIDADES ECONÔMICAS E SEÇÃO CNAE 2.0 EM JULHO DE 2026 - SEM AJUSTES
B19: SÉRIES HISTÓRICAS
B20: 5 | C20: =#REF! -> #REF!
B21: 6 | C21: =#REF! -> #REF!
B22: 7 | C22: ='Tabela 6'!B2 -> TABELA 6 - EVOLUÇÃO MENSAL DE ESTOQUE, ADMISSÕES, DESLIGAMENTOS E SALDO POR GRUPAMENTO DE ATIVIDADES ECONÔMICAS - SÉRIE SEM AJUSTES
B23: 8 | C23: ='Tabela 6.1'!B2 -> TABELA 6.1 - EVOLUÇÃO MENSAL DE ESTOQUE, ADMISSÕES, DESLIGAMENTOS E SALDO POR GRUPAMENTO DE ATIVIDADES ECONÔMICAS - SÉRIE COM AJUSTES
B24: 9 | C24: =#REF! -> #REF!
B25: 10 | C25: =#REF! -> #REF!
B26: 11 | C26: =#REF! -> #REF!
B27: 12 | C27: =#REF! -> #REF!
B28: 13 | C28: ='Tabela 9'!B2 -> TABELA 9 - EVOLUÇÃO DO SALÁRIO MÉDIO REAL DE ADMISSÃO E DESLIGAMENTO POR MÊS - SEM AJUSTES
B29: 14 | C29: =#REF! -> #REF!
B30: 15 | C30: ='Tabela 11'!B2 -> TABELA 11 - TAXA DE ROTATIVIDADE POR NÍVEL GEOGRÁFICO - AGOSTO DE 2025 A JULHO DE 2026

Sheet Tabela 4
B2: TABELA 4 - SALDO POR UNIDADE DA FEDERAÇÃO, GRUPAMENTO DE ATIVIDADES ECONÔMICAS E SEÇÃO CNAE 2.0 EM JULHO DE 2026 - SEM AJUSTES
B5: Grupamento de Atividades Econômicas e Seção CNAE 2.0 | C5: Unidade da Federação
C6: Rondônia | D6: Acre | E6: Amazonas | F6: Roraima | G6: Pará | H6: Amapá | I6: Tocantins | J6: Maranhão | K6: Piauí | L6: Ceará | M6: Rio Grande do Norte | N6: Paraíba | O6: Pernambuco | P6: Alagoas | Q6: Sergipe | R6: Bahia | S6: Minas Gerais | T6: Espírito Santo | U6: Rio de Janeiro | V6: São Paulo | W6: Paraná | X6: Santa Catarina | Y6: Rio Grande do Sul | Z6: Mato Grosso do Sul | AA6: Mato Grosso | AB6: Goiás | AC6: Distrito Federal | AD6: Não identificado | AE6: Total
B7: Total | C7: 199 | D7: 280 | E7: 3650 | F7: 386 | G7: 3816 | H7: 410 | I7: -366 | J7: 654 | K7: 1987 | L7: 4181 | M7: 999 | N7: 2307 | O7: 1883 | P7: 1203 | Q7: 1095 | R7: 4664 | S7: 5199 | T7: -2605 | U7: 1260 | V7: 17814 | W7: 523 | X7: -248 | Y7: -903 | Z7: 730 | AA7: 5766 | AB7: 3581 | AC7: -134 | AD7: 237 | AE7: 58568
B8: Agricultura, pecuária, produção florestal, pesca e aquicultura | C8: -38 | D8: 21 | E8: 138 | F8: -75 | G8: 710 | H8: 13 | I8: -188 | J8: -392 | K8: -41 | L8: 376 | M8: 1291 | N8: 152 | O8: 641 | P8: 316 | Q8: -50 | R8: 135 | S8: 1323 | T8: -5852 | U8: -40 | V8: 9298 | W8: -516 | X8: 75 | Y8: 189 | Z8: -213 | AA8: 3377 | AB8: 1754 | AC8: 150 | AD8: -31 | AE8: 12523
B9: Indústria geral | C9: 212 | D9: 54 | E9: 341 | F9: -64 | G9: 116 | H9: 43 | I9: 199 | J9: 153 | K9: 266 | L9: -408 | M9: 383 | N9: 1298 | O9: 916 | P9: 439 | Q9: 157 | R9: 2016 | S9: 412 | T9: 1841 | U9: -277 | V9: 2262 | W9: 223 | X9: -49 | Y9: -304 | Z9: -556 | AA9: 1095 | AB9: 527 | AC9: -28 | AD9: 48 | AE9: 11315
B10: Indústrias Extrativas | C10: 70 | D10: -2 | E10: -5 | F10: 2 | G10: -79 | H10: 18 | I10: -1 | J10: 9 | K10: -38 | L10: 19 | M10: -31 | N10: 7 | O10: 10 | P10: -10 | Q10: 21 | R10: 81 | S10: -171 | T10: -31 | U10: 89 | V10: -16 | W10: -4 | X10: -28 | Y10: -34 | Z10: 9 | AA10: 90 | AB10: 43 | AC10: 0 | AD10: 0 | AE10: 18
B11: Indústrias de Transformação | C11: 150 | D11: 54 | E11: 380 | F11: -34 | G11: 347 | H11: 38 | I11: 193 | J11: 153 | K11: 319 | L11: -258 | M11: 367 | N11: 1297 | O11: 798 | P11: 347 | Q11: 66 | R11: 1636 | S11: 496 | T11: 1853 | U11: -680 | V11: 1598 | W11: 229 | X11: 13 | Y11: -327 | Z11: -581 | AA11: 876 | AB11: 551 | AC11: -20 | AD11: 47 | AE11: 9908
B12: Eletricidade e Gás | C12: 18 | D12: -1 | E12: -1 | F12: -23 | G12: -26 | H12: -1 | I12: -11 | J12: -1 | K12: -3 | L12: 22 | M12: 28 | N12: -10 | O12: -29 | P12: 87 | Q12: -7 | R12: 263 | S12: -44 | T12: -4 | U12: 205 | V12: 83 | W12: -43 | X12: -27 | Y12: -17 | Z12: 12 | AA12: 25 | AB12: -41 | AC12: 3 | AD12: 0 | AE12: 457
B13: Água, Esgoto, Atividades de Gestão de Resíduos e Descontaminação | C13: -26 | D13: 3 | E13: -33 | F13: -9 | G13: -126 | H13: -12 | I13: 18 | J13: -8 | K13: -12 | L13: -191 | M13: 19 | N13: 4 | O13: 137 | P13: 15 | Q13: 77 | R13: 36 | S13: 131 | T13: 23 | U13: 109 | V13: 597 | W13: 41 | X13: -7 | Y13: 74 | Z13: 4 | AA13: 104 | AB13: -26 | AC13: -11 | AD13: 1 | AE13: 932
B14: Construção | C14: 42 | D14: -176 | E14: 582 | F14: 209 | G14: 1463 | H14: 109 | I14: -34 | J14: 379 | K14: 523 | L14: 1284 | M14: -271 | N14: 418 | O14: 265 | P14: -108 | Q14: 348 | R14: 670 | S14: 3337 | T14: 1018 | U14: 838 | V14: -1000 | W14: 188 | X14: -111 | Y14: -201 | Z14: 1188 | AA14: 191 | AB14: 1475 | AC14: 31 | AD14: 34 | AE14: 12691
B15: Comércio; reparação de veículos automotores e motocicletas | C15: -205 | D15: 41 | E15: 370 | F15: 60 | G15: 244 | H15: 125 | I15: -210 | J15: 212 | K15: 254 | L15: -3 | M15: 204 | N15: -132 | O15: -357 | P15: 52 | Q15: 35 | R15: -1193 | S15: -650 | T15: -3 | U15: -138 | V15: 1303 | W15: -869 | X15: -74 | Y15: -759 | Z15: -80 | AA15: -303 | AB15: -472 | AC15: 362 | AD15: 130 | AE15: -2056
B16: Serviços | C16: 188 | D16: 344 | E16: 2219 | F16: 256 | G16: 1283 | H16: 120 | I16: -133 | J16: 302 | K16: 985 | L16: 2931 | M16: -608 | N16: 571 | O16: 418 | P16: 504 | Q16: 607 | R16: 3037 | S16: 776 | T16: 391 | U16: 877 | V16: 5946 | W16: 1497 | X16: -89 | Y16: 172 | Z16: 391 | AA16: 1406 | AB16: 300 | AC16: -649 | AD16: 56 | AE16: 24098
B17: Transporte, armazenagem e correio | C17: -18 | D17: -122 | E17: 98 | F17: 49 | G17: 198 | H17: 18 | I17: -16 | J17: -3 | K17: 32 | L17: -16 | M17: 84 | N17: 57 | O17: 205 | P17: -57 | Q17: 74 | R17: 177 | S17: 2303 | T17: 289 | U17: 562 | V17: 8957 | W17: 728 | X17: 754 | Y17: 283 | Z17: -148 | AA17: -1 | AB17: 682 | AC17: 56 | AD17: -3 | AE17: 15222
B18: Alojamento e alimentação | C18: 75 | D18: 20 | E18: 64 | F18: 46 | G18: 295 | H18: 60 | I18: -17 | J18: 150 | K18: 180 | L18: 176 | M18: 78 | N18: -116 | O18: 116 | P18: -3 | Q18: -38 | R18: 208 | S18: -237 | T18: -129 | U18: -1006 | V18: -1754 | W18: -227 | X18: -337 | Y18: 44 | Z18: 38 | AA18: 356 | AB18: 152 | AC18: -17 | AD18: 12 | AE18: -1811
... B34: Não identificado | C34: 0 | D34: -4 | E34: 0 | F34: 0 | G34: 0 | H34: 0 | I34: 0 | J34: 0 | K34: 0 | L34: 1 | M34: 0 | N34: 0 | O34: 0 | P34: 0 | Q34: -2 | R34: -1 | S34: 1 | T34: 0 | U34: 0 | V34: 5 | W34: 0 | X34: 0 | Y34: 0 | Z34: 0 | AA34: 0 | AB34: -3 | AC34: 0 | AD34: 0 | AE34: -3
B37: Fonte: Novo Caged – MTE.

Sheet Tabela 6
B2: TABELA 6 - EVOLUÇÃO MENSAL DE ESTOQUE, ADMISSÕES, DESLIGAMENTOS E SALDO POR GRUPAMENTO DE ATIVIDADES ECONÔMICAS - SÉRIE SEM AJUSTES
B5: Grupamento de Atividades Econômicas e Seção CNAE 2.0 | C5: Janeiro/2020 | G5: Fevereiro/2020 | L5: Março/2020 | Q5: Abril/2020 | V5: Maio/2020 | AA5: Junho/2020 | AF5: Julho/2020 | AK5: Agosto/2020 | AP5: Setembro/2020 | AU5: Outubro/2020 | AZ5: Novembro/2020 | BE5: Dezembro/2020 | BJ5: Janeiro/2021 | BO5: Fevereiro/2021 | BT5: Março/2021 | BY5: Abril/2021 | CD5: Maio/2021 | CI5: Junho/2021 | CN5: Julho/2021 | CS5: Agosto/2021 | CX5: Setembro/2021 | DC5: Outubro/2021 | DH5: Novembro/2021 | DM5: Dezembro/2021 | DR5: Janeiro/2022 | DW5: Fevereiro/2022 | EB5: Março/2022 | EG5: Abril/2022 | EL5: Maio/2022 | EQ5: Junho/2022 | EV5: Julho/2022 | FA5: Agosto/2022 | FF5: Setembro/2022 | FK5: Outubro/2022 | FP5: Novembro/2022 | FU5: Dezembro/2022 | FZ5: Janeiro/2023 | GE5: Fevereiro/2023 | GJ5: Março/2023 | GO5: Abril/2023 | GT5: Maio/2023 | GY5: Junho/2023 | HD5: Julho/2023 | HI5: Agosto/2023 | HN5: Setembro/2023 | HS5: Outubro/2023 | HX5: Novembro/2023 | IC5: Dezembro/2023 | IH5: Janeiro/2024 | IM5: Fevereiro/2024 | IR5: Março/2024 | IW5: Abril/2024 | JB5: Maio/2024 | JG5: Junho/2024 | JL5: Julho/2024 | JQ5: Agosto/2024 | JV5: Setembro/2024 | KA5: Outubro/2024 | KF5: Novembro/2024 | KK5: Dezembro/2024 | KP5: Janeiro/2025 | KU5: Fevereiro/2025 | KZ5: Março/2025 | LE5: Abril/2025 | LJ5: Maio/2025 | LO5: Junho/2025 | LT5: Julho/2025 | LY5: Agosto/2025 | MD5: Setembro/2025 | MI5: Outubro/2025 | MN5: Novembro/2025 | MS5: Dezembro/2025 | MX5: Janeiro/2026 | NC5: Fevereiro/2026 | NH5: Março/2026 | NM5: Abril/2026 | NR5: Maio/2026 | NW5: Junho/2026 | OB5: Julho/2026 | OG5: Acumulado do Ano (2026) - sem ajustes | OK5: Últimos 12 Meses** (Ago/25 a Jul/26) - sem ajuste
C6: Estoque | D6: Admissões | E6: Desligamentos | F6: Saldos | G6: Estoque | H6: Admissões | I6: Desligamentos | J6: Saldos | K6: Variação Relativa (%) | L6: Estoque | M6: Admissões | N6: Desligamentos | O6: Saldos | P6: Variação Relativa (%) | Q6: Estoque | R6: Admissões | S6: Desligamentos | T6: Saldos | U6: Variação Relativa (%) | V6: Estoque | W6: Admissões | X6: Desligamentos | Y6: Saldos | Z6: Variação Relativa (%) | AA6: Estoque | AB6: Admissões | AC6: Desligamentos | AD6: Saldos | AE6: Variação Relativa (%) | AF6: Estoque | AG6: Admissões | AH6: Desligamentos | AI6: Saldos | AJ6: Variação Relativa (%) | AK6: Estoque | AL6: Admissões | AM6: Desligamentos | AN6: Saldos | AO6: Variação Relativa (%) | AP6: Estoque | AQ6: Admissões | AR6: Desligamentos | AS6: Saldos | AT6: Variação Relativa (%) | AU6: Estoque | AV6: Admissões | AW6: Desligamentos | AX6: Saldos | AY6: Variação Relativa (%) | AZ6: Estoque | BA6: Admissões | BB6: Desligamentos | BC6: Saldos | BD6: Variação Relativa (%) | BE6: Estoque | BF6: Admissões | BG6: Desligamentos | BH6: Saldos | BI6: Variação Relativa (%) | BJ6: Estoque | BK6: Admissões | BL6: Desligamentos | BM6: Saldos | BN6: Variação Relativa (%) | BO6: Estoque | BP6: Admissões | BQ6: Desligamentos | BR6: Saldos | BS6: Variação Relativa (%) | BT6: Estoque | BU6: Admissões | BV6: Desligamentos | BW6: Saldos | BX6: Variação Relativa (%) | BY6: Estoque | BZ6: Admissões | CA6: Desligamentos | CB6: Saldos | CC6: Variação Relativa (%) | CD6: Estoque | CE6: Admissões | CF6: Desligamentos | CG6: Saldos | CH6: Variação Relativa (%) | CI6: Estoque | CJ6: Admissões | CK6: Desligamentos | CL6: Saldos | CM6: Variação Relativa (%) | CN6: Estoque | CO6: Admissões | CP6: Desligamentos | CQ6: Saldos | CR6: Variação Relativa (%) | CS6: Estoque | CT6: Admissões | CU6: Desligamentos | CV6: Saldos | CW6: Variação Relativa (%) | CX6: Estoque | CY6: Admissões | CZ6: Desligamentos | DA6: Saldos | DB6: Variação Relativa (%) | DC6: Estoque | DD6: Admissões | DE6: Desligamentos | DF6: Saldos | DG6: Variação Relativa (%) | DH6: Estoque | DI6: Admissões | DJ6: Desligamentos | DK6: Saldos | DL6: Variação Relativa (%) | DM6: Estoque | DN6: Admissões | DO6: Desligamentos | DP6: Saldos | DQ6: Variação Relativa (%) | DR6: Estoque | DS6: Admissões | DT6: Desligamentos | DU6: Saldos | DV6: Variação Relativa (%) | DW6: Estoque | DX6: Admissões | DY6: Desligamentos | DZ6: Saldos | EA6: Variação Relativa (%) | EB6: Estoque | EC6: Admissões | ED6: Desligamentos | EE6: Saldos | EF6: Variação Relativa (%) | EG6: Estoque | EH6: Admissões | EI6: Desligamentos | EJ6: Saldos | EK6: Variação Relativa (%) | EL6: Estoque | EM6: Admissões | EN6: Desligamentos | EO6: Saldos | EP6: Variação Relativa (%) | EQ6: Estoque | ER6: Admissões | ES6: Desligamentos | ET6: Saldos | EU6: Variação Relativa (%) | EV6: Estoque | EW6: Admissões | EX6: Desligamentos | EY6: Saldos | EZ6: Variação Relativa (%) | FA6: Estoque | FB6: Admissões | FC6: Desligamentos | FD6: Saldos | FE6: Variação Relativa (%) | FF6: Estoque | FG6: Admissões | FH6: Desligamentos | FI6: Saldos | FJ6: Variação Relativa (%) | FK6: Estoque | FL6: Admissões | FM6: Desligamentos | FN6: Saldos | FO6: Variação Relativa (%) | FP6: Estoque | FQ6: Admissões | FR6: Desligamentos | FS6: Saldos | FT6: Variação Relativa (%) | FU6: Estoque | FV6: Admissões | FW6: Desligamentos | FX6: Saldos | FY6: Variação Relativa (%) | FZ6: Estoque | GA6: Admissões | GB6: Desligamentos | GC6: Saldos | GD6: Variação Relativa (%) | GE6: Estoque | GF6: Admissões | GG6: Desligamentos | GH6: Saldos | GI6: Variação Relativa (%) | GJ6: Estoque | GK6: Admissões | GL6: Desligamentos | GM6: Saldos | GN6: Variação Relativa (%) | GO6: Estoque | GP6: Admissões | GQ6: Desligamentos | GR6: Saldos | GS6: Variação Relativa (%) | GT6: Estoque | GU6: Admissões | GV6: Desligamentos | GW6: Saldos | GX6: Variação Relativa (%) | GY6: Estoque | GZ6: Admissões | HA6: Desligamentos | HB6: Saldos | HC6: Variação Relativa (%) | HD6: Estoque | HE6: Admissões | HF6: Desligamentos | HG6: Saldos | HH6: Variação Relativa (%) | HI6: Estoque | HJ6: Admissões | HK6: Desligamentos | HL6: Saldos | HM6: Variação Relativa (%) | HN6: Estoque | HO6: Admissões | HP6: Desligamentos | HQ6: Saldos | HR6: Variação Relativa (%) | HS6: Estoque | HT6: Admissões | HU6: Desligamentos | HV6: Saldos | HW6: Variação Relativa (%) | HX6: Estoque | HY6: Admissões | HZ6: Desligamentos | IA6: Saldos | IB6: Variação Relativa (%) | IC6: Estoque | ID6: Admissões | IE6: Desligamentos | IF6: Saldos | IG6: Variação Relativa (%) | IH6: Estoque | II6: Admissões | IJ6: Desligamentos | IK6: Saldos | IL6: Variação Relativa (%) | IM6: Estoque | IN6: Admissões | IO6: Desligamentos | IP6: Saldos | IQ6: Variação Relativa (%) | IR6: Estoque | IS6: Admissões | IT6: Desligamentos | IU6: Saldos | IV6: Variação Relativa (%) | IW6: Estoque | IX6: Admissões | IY6: Desligamentos | IZ6: Saldos | JA6: Variação Relativa (%) | JB6: Estoque | JC6: Admissões | JD6: Desligamentos | JE6: Saldos | JF6: Variação Relativa (%) | JG6: Estoque | JH6: Admissões | JI6: Desligamentos | JJ6: Saldos | JK6: Variação Relativa (%) | JL6: Estoque | JM6: Admissões | JN6: Desligamentos | JO6: Saldos | JP6: Variação Relativa (%) | JQ6: Estoque | JR6: Admissões | JS6: Desligamentos | JT6: Saldos | JU6: Variação Relativa (%) | JV6: Estoque | JW6: Admissões | JX6: Desligamentos | JY6: Saldos | JZ6: Variação Relativa (%) | KA6: Estoque | KB6: Admissões | KC6: Desligamentos | KD6: Saldos | KE6: Variação Relativa (%) | KF6: Estoque | KG6: Admissões | KH6: Desligamentos | KI6: Saldos | KJ6: Variação Relativa (%) | KK6: Estoque | KL6: Admissões | KM6: Desligamentos | KN6: Saldos | KO6: Variação Relativa (%) | KP6: Estoque | KQ6: Admissões | KR6: Desligamentos | KS6: Saldos | KT6: Variação Relativa (%) | KU6: Estoque | KV6: Admissões | KW6: Desligamentos | KX6: Saldos | KY6: Variação Relativa (%) | KZ6: Estoque | LA6: Admissões | LB6: Desligamentos | LC6: Saldos | LD6: Variação Relativa (%) | LE6: Estoque | LF6: Admissões | LG6: Desligamentos | LH6: Saldos | LI6: Variação Relativa (%) | LJ6: Estoque | LK6: Admissões | LL6: Desligamentos | LM6: Saldos | LN6: Variação Relativa (%) | LO6: Estoque | LP6: Admissões | LQ6: Desligamentos | LR6: Saldos | LS6: Variação Relativa (%) | LT6: Estoque | LU6: Admissões | LV6: Desligamentos | LW6: Saldos | LX6: Variação Relativa (%) | LY6: Estoque | LZ6: Admissões | MA6: Desligamentos | MB6: Saldos | MC6: Variação Relativa (%) | MD6: Estoque | ME6: Admissões | MF6: Desligamentos | MG6: Saldos | MH6: Variação Relativa (%) | MI6: Estoque | MJ6: Admissões | MK6: Desligamentos | ML6: Saldos | MM6: Variação Relativa (%) | MN6: Estoque | MO6: Admissões | MP6: Desligamentos | MQ6: Saldos | MR6: Variação Relativa (%) | MS6: Estoque**** (Estoque de referência de 2024) | MT6: Admissões | MU6: Desligamentos | MV6: Saldos | MW6: Variação Relativa (%) | MX6: Estoque | MY6: Admissões | MZ6: Desligamentos | NA6: Saldos | NB6: Variação Relativa (%) | NC6: Estoque | ND6: Admissões | NE6: Desligamentos | NF6: Saldos | NG6: Variação Relativa (%) | NH6: Estoque | NI6: Admissões | NJ6: Desligamentos | NK6: Saldos | NL6: Variação Relativa (%) | NM6: Estoque | NN6: Admissões | NO6: Desligamentos | NP6: Saldos | NQ6: Variação Relativa (%) | NR6: Estoque | NS6: Admissões | NT6: Desligamentos | NU6: Saldos | NV6: Variação Relativa (%) | NW6: Estoque | NX6: Admissões | NY6: Desligamentos | NZ6: Saldos | OA6: Variação Relativa (%) | OB6: Estoque | OC6: Admissões | OD6: Desligamentos | OE6: Saldos | OF6: Variação Relativa (%) | OG6: Admissões | OH6: Desligamentos | OI6: Saldos | OJ6: Variação Relativa (%) | OK6: Admissões | OL6: Desligamentos | OM6: Saldos | ON6: Variação Relativa (%)
B7: Total | C7: =G7-J7 -> 37756445 | D7: 1384986 | E7: 1292308 | F7: 92678 | G7: =L7-O7 -> 37954813 | H7: 1483832 | I7: 1285464 | J7: 198368 | K7: =(J7/C7)*100 -> 0.52538845 | L7: =Q7-T7 -> 37722497 | M7: 1347665 | N7: 1579981 | O7: -232316 | P7: =(O7/G7)*100 -> -0.61208575 | Q7: =V7-Y7 -> 36820180 | R7: 617644 | S7: 1519961 | T7: -902317 | U7: =(T7/L7)*100 -> -2.3919864 | V7: =AA7-AD7 -> 36467390 | W7: 716330 | X7: 1069120 | Y7: -352790 | Z7: =(Y7/Q7)*100 -> -0.95814306 | AA7: =AF7-AI7 -> 36444279 | AB7: 910176 | AC7: 933287 | AD7: -23111 | AE7: =(AD7/V7)*100 -> -0.063374428 | AF7: =AK7-AN7 -> 36567576 | AG7: 1061898 | AH7: 938601 | AI7: 123297 | AJ7: =(AI7/AA7)*100 -> 0.33831647 | AK7: =AP7-AS7 -> 36805701 | AL7: 1257362 | AM7: 1019237 | AN7: 238125 | AO7: =(AN7/AF7)*100 -> 0.65119165 | AP7: =AU7-AX7 -> 37119265 | AQ7: 1406746 | AR7: 1093182 | AS7: 313564 | AT7: =(AS7/AK7)*100 -> 0.85194411 | AU7: =AZ7-BC7 -> 37508203 | AV7: 1571402 | AW7: 1182464 | AX7: 388938 | AY7: =(AX7/AP7)*100 -> 1.0478063 | AZ7: =BE7-BH7 -> 37917151 | BA7: 1552837 | BB7: 1143889 | BC7: 408948 | BD7: =(BC7/AU7)*100 -> 1.0902895 | BE7: =BJ7-BM7 -> 37835033 | BF7: 1256247 | BG7: 1338365 | BH7: -82118 | BI7: =(BH7/AZ7)*100 -> -0.21657218 | BJ7: =BO7-BR7 -> 38092092 | BK7: 1550075 | BL7: 1293016 | BM7: 257059 | BN7: =(BM7/BE7)*100 -> 0.67942058 | BO7: =BT7-BW7 -> 38490007 | BP7: 1715425 | BQ7: 1317510 | BR7: 397915 | BS7: =(BR7/BJ7)*100 -> 1.0446131 | BT7: =BY7-CB7 -> 38666337 | BU7: 1626885 | BV7: 1450555 | BW7: 176330 | BX7: =(BW7/BO7)*100 -> 0.45811891 | BY7: =CD7-CG7 -> 38780259 | BZ7: 1396311 | CA7: 1282389 | CB7: 113922 | CC7: =(CB7/BT7)*100 -> 0.29462837 | CD7: =CI7-CL7 -> 39058964 | CE7: 1558316 | CF7: 1279611 | CG7: 278705 | CH7: =(CG7/BY7)*100 -> 0.71867751 | CI7: =CN7-CQ7 -> 39369000 | CJ7: 1609748 | CK7: 1299712 | CL7: 310036 | CM7: =(CL7/CD7)*100 -> 0.79376401 | CN7: =CS7-CV7 -> 39685725 | CO7: 1666051 | CP7: 1349326 | CQ7: 316725 | CR7: =(CQ7/CI7)*100 -> 0.80450354 | CS7: =CX7-DA7 -> 40059069 | CT7: 1819411 | CU7: 1446067 | CV7: 373344 | CW7: =(CV7/CN7)*100 -> 0.94075137 | CX7: =DC7-DF7 -> 40376062 | CY7: 1789967 | CZ7: 1472974 | DA7: 316993 | DB7: =(DA7/CS7)*100 -> 0.79131395 | DC7: =DH7-DK7 -> 40629145 | DD7: =DE7+DF7 -> 1760739 | DE7: 1507656 | DF7: 253083 | DG7: =(DF7/CX7)*100 -> 0.62681447 | DH7: =DM7-DP7 -> 40953257 | DI7: 1772766 | DJ7: 1448654 | DK7: 324112 | DL7: =(DK7/DC7)*100 -> 0.79773276 | DM7: =DR7-DU7 -> 40687446 | DN7: 1437910 | DO7: 1703721 | DP7: -265811 | DQ7: =(DP7/DH7)*100 -> -0.64905949 | DR7: =DW7-DZ7 -> 40842624 | DS7: 1777646 | DT7: 1622468 | DU7: 155178 | DV7: =(DU7/DM7)*100 -> 0.38139037 | DW7: =EB7-EE7 -> 41171131 | DX7: 2013143 | DY7: 1684636 | DZ7: 328507 | EA7: =(DZ7/DR7)*100 -> 0.80432393 | EB7: =EG7-EJ7 -> 41307320 | EC7: 1953071 | ED7: 1816882 | EE7: 136189 | EF7: =(EE7/DW7)*100 -> 0.33078761 | EG7: =EL7-EO7 -> 41504286 | EH7: 1854557 | EI7: 1657591 | EJ7: 196966 | EK7: =(EJ7/EB7)*100 -> 0.47683074 | EL7: =EQ7-ET7 -> 41781304 | EM7: 1960960 | EN7: 1683942 | EO7: 277018 | EP7: =(EO7/EG7)*100 -> 0.66744432 | EQ7: =EV7-EY7 -> 42059248 | ER7: 1898876 | ES7: 1620932 | ET7: 277944 | EU7: =(ET7/EL7)*100 -> 0.66523534 | EV7: =FA7-FD7 -> 42278150 | EW7: 1886537 | EX7: 1667635 | EY7: 218902 | EZ7: =(EY7/EQ7)*100 -> 0.52046104 | FA7: =FF7-FI7 -> 42556789 | FB7: 2051800 | FC7: 1773161 | FD7: 278639 | FE7: =(FD7/EV7)*100 -> 0.65906148 | FF7: =FK7-FN7 -> 42834874 | FG7: 1926572 | FH7: 1648487 | FI7: 278085 | FJ7: =(FI7/FA7)*100 -> 0.65344451 | FK7: =FP7-FS7 -> 42994328 | FL7: 1789462 | FM7: 1630008 | FN7: 159454 | FO7: =(FN7/FF7)*100 -> 0.37225276 | FP7: =FU7-FX7 -> 43129823 | FQ7: 1747894 | FR7: 1612399 | FS7: 135495 | FT7: =(FS7/FK7)*100 -> 0.31514622 | FU7: =FZ7-GC7 -> 42698812 | FV7: 1382923 | FW7: 1813934 | FX7: -431011 | FY7: =(FX7/FP7)*100 -> -0.99933403 | FZ7: =GE7-GH7 -> 42782109 | GA7: 1874226 | GB7: 1790929 | GC7: 83297 | GD7: =(GC7/FU7)*100 -> 0.19508037 | GE7: =GJ7-GM7 -> 43023894 | GF7: 1949844 | GG7: 1708059 | GH7: 241785 | GI7: =(GH7/FZ7)*100 -> 0.56515447 | GJ7: =GO7-GR7 -> 43219065 | GK7: 2168418 | GL7: 1973247 | GM7: 195171 | GN7: =(GM7/GE7)*100 -> 0.45363397 | GO7: =GT7-GW7 -> 43399070 | GP7: 1865279 | GQ7: 1685274 | GR7: 180005 | GS7: =(GR7/GJ7)*100 -> 0.41649443 | GT7: =GY7-HB7 -> 43554340 | GU7: 2000202 | GV7: 1844932 | GW7: 155270 | GX7: =(GW7/GO7)*100 -> 0.35777264 | GY7: =HD7-HG7 -> 43711538 | GZ7: 1914130 | HA7: 1756932 | HB7: 157198 | HC7: =(HB7/GT7)*100 -> 0.36092385 | HD7: =HI7-HL7 -> 43854240 | HE7: 1883198 | HF7: 1740496 | HG7: 142702 | HH7: =(HG7/GY7)*100 -> 0.326463 | HI7: =HN7-HQ7 -> 44075084 | HJ7: 2099211 | HK7: 1878367 | HL7: 220844 | HM7: =(HL7/HD7)*100 -> 0.50358643 | HN7: =HS7-HV7 -> 44286848 | HO7: 1917057 | HP7: 1705293 | HQ7: 211764 | HR7: =(HQ7/HI7)*100 -> 0.48046193 | HS7: =HX7-IA7 -> 44477214 | HT7: 1941281 | HU7: 1750915 | HV7: 190366 | HW7: =(HV7/HN7)*100 -> 0.42984771 | HX7: =IC7-IF7 -> 44607311 | HY7: 1866752 | HZ7: 1736655 | IA7: 130097 | IB7: =(IA7/HS7)*100 -> 0.29250258 | IC7: =IH7-IK7 -> 44177152 | ID7: 1502563 | IE7: 1932722 | IF7: -430159 | IG7: =(IF7/HX7)*100 -> -0.96432399 | IH7: =IM7-IP7 -> 44357547 | II7: 2067817 | IJ7: 1887422 | IK7: 180395 | IL7: =(IK7/IC7)*100 -> 0.40834457 | IM7: =IR7-IU7 -> 44663658 | IN7: =SUM(IN8,IN9,IN14,IN15,IN16,IN34) -> 2249070 | IO7: =SUM(IO8,IO9,IO14,IO15,IO16,IO34) -> 1942959 | IP7: =SUM(IP8,IP9,IP14,IP15,IP16,IP34) -> 306111 | IQ7: =(IP7/IH7)*100 -> 0.69009903 | IR7: =IW7-IZ7 -> 44907973 | IS7: 2262420 | IT7: 2018105 | IU7: 244315 | IV7: =(IU7/IM7)*100 -> 0.54701073 | IW7: =JB7-JE7 -> 45148006 | IX7: 2260439 | IY7: 2020406 | IZ7: 240033 | JA7: =(IZ7/IR7)*100 -> 0.53449974 | JB7: =JG7-JJ7 -> 45279817 | JC7: 2116326 | JD7: 1984515 | JE7: 131811 | JF7: =(JE7/IW7)*100 -> 0.29195309 | JG7: =JL7-JO7 -> 45481522 | JH7: 2071649 | JI7: 1869944 | JJ7: 201705 | JK7: =(JJ7/JB7)*100 -> 0.44546337 | JL7: =JQ7-JT7 -> 45669543 | JM7: 2187633 | JN7: 1999612 | JO7: 188021 | JP7: =(JO7/JG7)*100 -> 0.41340085 | JQ7: =JV7-JY7 -> 45902056 | JR7: 2231410 | JS7: 1998897 | JT7: 232513 | JU7: =(JT7/JL7)*100 -> 0.50912049 | JV7: =KA7-KD7 -> 46149874 | JW7: 2163929 | JX7: 1916111 | JY7: 247818 | JZ7: =(JY7/JQ7)*100 -> 0.53988431 | KA7: =KF7-KI7 -> 46282588 | KB7: 2222962 | KC7: 2090248 | KD7: 132714 | KE7: =(KD7/JV7)*100 -> 0.28757175 | KF7: =KK7-KN7 -> 46389213 | KG7: 1978371 | KH7: 1871746 | KI7: 106625 | KJ7: =(KI7/KA7)*100 -> 0.23037821 | KK7: =KP7-KS7 -> 45853666 | KL7: 1524251 | KM7: 2059798 | KN7: -535547 | KO7: =(KN7/KF7)*100 -> -1.1544645 | KP7: =KU7-KX7 -> 45990969 | KQ7: 2271611 | KR7: 2134308 | KS7: 137303 | KT7: =(KS7/KK7)*100 -> 0.29943734 | KU7: =KZ7-LC7 -> 46422964 | KV7: 2579192 | KW7: 2147197 | KX7: 431995 | KY7: =(KX7/KP7)*100 -> 0.93930398 | KZ7: =LE7-LH7 -> 46494540 | LA7: 2234662 | LB7: 2163086 | LC7: 71576 | LD7: =(LC7/KU7)*100 -> 0.15418231 | LE7: =LJ7-LM7 -> 46752068 | LF7: 2282187 | LG7: 2024659 | LH7: 257528 | LI7: =(LH7/KZ7)*100 -> 0.55388869 | LJ7: =LO7-LR7 -> 46901060 | LK7: 2256225 | LL7: 2107233 | LM7: 148992 | LN7: =(LM7/LE7)*100 -> 0.31868537 | LO7: =LT7-LW7 -> 47067681 | LP7: 2139182 | LQ7: 1972561 | LR7: 166621 | LS7: =(LR7/LJ7)*100 -> 0.35526063 | LT7: =LY7-MB7 -> 47197456 | LU7: 2251440 | LV7: 2121665 | LW7: 129775 | LX7: =(LW7/LO7)*100 -> 0.27571998 | LY7: =MD7-MG7 -> 47344814 | LZ7: 2239895 | MA7: 2092537 | MB7: 147358 | MC7: =(MB7/LT7)*100 -> 0.31221598 | MD7: =MI7-ML7 -> 47557816 | ME7: 2292492 | MF7: 2079490 | MG7: 213002 | MH7: =(MG7/LY7)*100 -> 0.4498951 | MI7: =MN7-MQ7 -> 47642963 | MJ7: 2271460 | MK7: 2186313 | ML7: 85147 | MM7: =(ML7/MD7)*100 -> 0.17903892 | MN7: =MS7-MV7 -> 47728827 | MO7: 1979902 | MP7: 1894038 | MQ7: 85864 | MR7: =(MQ7/MI7)*100 -> 0.18022389 | MS7: 47110663 | MT7: 1523309 | MU7: 2141473 | MV7: -618164 | MW7: =(MV7/MN7)*100 -> -1.2951586 | MX7: =MS7+NA7 -> 47222997 | MY7: 2208030 | MZ7: 2095696 | NA7: 112334 | NB7: 0.23178068 | NC7: =MX7+NF7 -> 47478318 | ND7: 2381767 | NE7: 0 | NF7: 255321 | NG7: =(NF7/NC7)*100 -> 0.53776336 | NH7: =NC7+NK7 -> 47706526 | NI7: 2526660 | NJ7: 2298452 | NK7: 228208 | NL7: =(NK7/NH7)*100 -> 0.47835803 | NM7: =NH7+NP7 -> 47792414 | NN7: 2268655 | NO7: 2182767 | NP7: 85888 | NQ7: 0.17996612 | NR7: =NM7+NU7 -> 47865374 | NS7: 2207303 | NT7: 2134343 | NU7: 72960 | NV7: 0.15261993 | NW7: =NR7+NZ7 -> 48010535 | NX7: 2220131 | NY7: 2074970 | NZ7: 145161 | OA7: 0.30313143 | OB7: =NW7+OE7 -> 48069103 | OC7: 2262888 | OD7: 2204320 | OE7: 58568 | OF7: 0.121955 | OG7: =SUM(ND7,MY7,NI7,NN7,NS7,NX7,OC7) -> 16075434 | OH7: =SUM(NE7,MZ7,NJ7,NO7,NT7,NY7,OD7) -> 12990548 | OI7: =SUM(NF7,NA7,NK7,NP7,NU7,NZ7,OE7) -> 958440 | OJ7: =(OI7/MS7)*100 -> 2.0344439 | OK7: =SUM(MT7,MO7,MJ7,ME7,LZ7,MY7,ND7,NI7,NN7,NS7,NX7,OC7) -> 26382492 | OL7: =SUM(MU7,MP7,MK7,MF7,MA7,MZ7,NE7,NJ7,NO7,NT7,NY7,OD7) -> 23384399 | OM7: =SUM(MV7,MQ7,ML7,MG7,MB7,NA7,NF7,NK7,NP7,NU7,NZ7,OE7) -> 871647 | ON7: =OM7/(OB7-OM7)*100 -> 1.8468093
B8: Agricultura, pecuária, produção florestal, pesca e aquicultura | C8: =G8-J8 -> 1473456 | D8: 69520 | E8: 53425 | F8: 16095 | G8: =L8-O8 -> 1478398 | H8: 70254 | I8: 65312 | J8: 4942 | K8: =(J8/C8)*100 -> 0.33540194 | L8: =Q8-T8 -> 1473949 | M8: 68635 | N8: 73084 | O8: -4449 | P8: =(O8/G8)*100 -> -0.30093385 | Q8: =V8-Y8 -> 1468508 | R8: 52759 | S8: 58200 | T8: -5441 | U8: =(T8/L8)*100 -> -0.36914439 | V8: =AA8-AD8 -> 1484288 | W8: 69794 | X8: 54014 | Y8: 15780 | Z8: =(Y8/Q8)*100 -> 1.07456 | AA8: =AF8-AI8 -> 1521117 | AB8: 84013 | AC8: 47184 | AD8: 36829 | AE8: =(AD8/V8)*100 -> 2.481257 | AF8: =AK8-AN8 -> 1544082 | AG8: 73886 | AH8: 50921 | AI8: 22965 | AJ8: =(AI8/AA8)*100 -> 1.5097458 | AK8: =AP8-AS8 -> 1554766 | AL8: 66190 | AM8: 55506 | AN8: 10684 | AO8: =(AN8/AF8)*100 -> 0.69193216 | AP8: =AU8-AX8 -> 1562686 | AQ8: 68302 | AR8: 60382 | AS8: 7920 | AT8: =(AS8/AK8)*100 -> 0.50940141 | AU8: =AZ8-BC8 -> 1562389 | AV8: 65023 | AW8: 65320 | AX8: -297 | AY8: =(AX8/AP8)*100 -> -0.019005738 | AZ8: =BE8-BH8 -> 1546068 | BA8: 55550 | BB8: 71871 | BC8: -16321 | BD8: =(BC8/AU8)*100 -> -1.0446182 | BE8: =BJ8-BM8 -> 1522300 | BF8: 45905 | BG8: 69673 | BH8: -23768 | BI8: =(BH8/AZ8)*100 -> -1.5373192 | BJ8: =BO8-BR8 -> 1555183 | BK8: 88199 | BL8: 55316 | BM8: 32883 | BN8: =(BM8/BE8)*100 -> 2.1600867 | BO8: =BT8-BW8 -> 1578058 | BP8: 87523 | BQ8: 64648 | BR8: 22875 | BS8: =(BR8/BJ8)*100 -> 1.470888 | BT8: =BY8-CB8 -> 1581468 | BU8: 89350 | BV8: 85940 | BW8: 3410 | BX8: =(BW8/BO8)*100 -> 0.21608838 | BY8: =CD8-CG8 -> 1592594 | BZ8: 85399 | CA8: 74273 | CB8: 11126 | CC8: =(CB8/BT8)*100 -> 0.70352356 | CD8: =CI8-CL8 -> 1634874 | CE8: 105783 | CF8: 63503 | CG8: 42280 | CH8: =(CG8/BY8)*100 -> 2.6547884 | CI8: =CN8-CQ8 -> 1673255 | CJ8: 104436 | CK8: 66055 | CL8: 38381 | CM8: =(CL8/CD8)*100 -> 2.3476427 | CN8: =CS8-CV8 -> 1698775 | CO8: 93045 | CP8: 67525 | CQ8: 25520 | CR8: =(CQ8/CI8)*100 -> 1.525171 | CS8: =CX8-DA8 -> 1707885 | CT8: 84941 | CU8: 75831 | CV8: 9110 | CW8: =(CV8/CN8)*100 -> 0.53626878 | CX8: =DC8-DF8 -> 1716771 | CY8: 90004 | CZ8: 81118 | DA8: 8886 | DB8: =(DA8/CS8)*100 -> 0.52029264 | DC8: =DH8-DK8 -> 1710927 | DD8: 83540 | DE8: 89384 | DF8: -5844 | DG8: =(DF8/CX8)*100 -> -0.3404065 | DH8: =DM8-DP8 -> 1694130 | DI8: 73989 | DJ8: 90786 | DK8: -16797 | DL8: =(DK8/DC8)*100 -> -0.98174849 | DM8: =DR8-DU8 -> 1668057 | DN8: 63456 | DO8: 89529 | DP8: -26073 | DQ8: =(DP8/DH8)*100 -> -1.53902 | DR8: =DW8-DZ8 -> 1693071 | DS8: 106242 | DT8: 81228 | DU8: 25014 | DV8: =(DU8/DM8)*100 -> 1.499589 | DW8: =EB8-EE8 -> 1710486 | DX8: 104570 | DY8: 87155 | DZ8: 17415 | EA8: =(DZ8/DR8)*100 -> 1.0286042 | EB8: =EG8-EJ8 -> 1694491 | EC8: 98510 | ED8: 114505 | EE8: -15995 | EF8: =(EE8/DW8)*100 -> -0.93511435 | EG8: =EL8-EO8 -> 1693470 | EH8: 95820 | EI8: 96841 | EJ8: -1021 | EK8: =(EJ8/EB8)*100 -> -0.060254082 | EL8: =EQ8-ET8 -> 1720217 | EM8: 121088 | EN8: 94341 | EO8: 26747 | EP8: =(EO8/EG8)*100 -> 1.5794198 | EQ8: =EV8-EY8 -> 1754677 | ER8: 123008 | ES8: 88548 | ET8: 34460 | EU8: =(ET8/EL8)*100 -> 2.0032356 | EV8: =FA8-FD8 -> 1770547 | EW8: 103950 | EX8: 88080 | EY8: 15870 | EZ8: =(EY8/EQ8)*100 -> 0.90443996 | FA8: =FF8-FI8 -> 1778271 | FB8: 103696 | FC8: 95972 | FD8: 7724 | FE8: =(FD8/EV8)*100 -> 0.43624936 | FF8: =FK8-FN8 -> 1787745 | FG8: 99961 | FH8: 90487 | FI8: 9474 | FJ8: =(FI8/FA8)*100 -> 0.53276469 | FK8: =FP8-FS8 -> 1786310 | FL8: 91032 | FM8: 92467 | FN8: -1435 | FO8: =(FN8/FF8)*100 -> -0.080268718 | FP8: =FU8-FX8 -> 1768099 | FQ8: 80060 | FR8: 98271 | FS8: -18211 | FT8: =(FS8/FK8)*100 -> -1.0194759 | FU8: =FZ8-GC8 -> 1731178 | FV8: 63391 | FW8: 100312 | FX8: -36921 | FY8: =(FX8/FP8)*100 -> -2.0881749 | FZ8: =GE8-GH8 -> 1754325 | GA8: 111632 | GB8: 88485 | GC8: 23147 | GD8: =(GC8/FU8)*100 -> 1.3370664 | GE8: =GJ8-GM8 -> 1770609 | GF8: 104811 | GG8: 88527 | GH8: 16284 | GI8: =(GH8/FZ8)*100 -> 0.92822026 | GJ8: =GO8-GR8 -> 1770277 | GK8: 117601 | GL8: 117933 | GM8: -332 | GN8: =(GM8/GE8)*100 -> -0.018750611 | GO8: =GT8-GW8 -> 1773179 | GP8: 103483 | GQ8: 100581 | GR8: 2902 | GS8: =(GR8/GJ8)*100 -> 0.16392915 | GT8: =GY8-HB8 -> 1792738 | GU8: 128396 | GV8: 108837 | GW8: 19559 | GX8: =(GW8/GO8)*100 -> 1.1030471 | GY8: =HD8-HG8 -> 1819897 | GZ8: 125832 | HA8: 98673 | HB8: 27159 | HC8: =(HB8/GT8)*100 -> 1.5149453 | HD8: =HI8-HL8 -> 1832875 | HE8: 104362 | HF8: 91384 | HG8: 12978 | HH8: =(HG8/GY8)*100 -> 0.71311728 | HI8: =HN8-HQ8 -> 1838001 | HJ8: 105218 | HK8: 100092 | HL8: 5126 | HM8: =(HL8/HD8)*100 -> 0.27966992 | HN8: =HS8-HV8 -> 1843943 | HO8: 97457 | HP8: 91515 | HQ8: 5942 | HR8: =(HQ8/HI8)*100 -> 0.323286 | HS8: =HX8-IA8 -> 1842287 | HT8: 94611 | HU8: 96267 | HV8: -1656 | HW8: =(HV8/HN8)*100 -> -0.089807548 | HX8: =IC8-IF8 -> 1821270 | HY8: 81983 | HZ8: 103000 | IA8: -21017 | IB8: =(IA8/HS8)*100 -> -1.1408103 | IC8: =IH8-IK8 -> 1767610 | ID8: 62078 | IE8: 115738 | IF8: -53660 | IG8: =(IF8/HX8)*100 -> -2.9462957 | IH8: =IM8-IP8 -> 1789510 | II8: 113538 | IJ8: 91638 | IK8: 21900 | IL8: =(IK8/IC8)*100 -> 1.2389611 | IM8: =IR8-IU8 -> 1793269 | IN8: 113369 | IO8: 109610 | IP8: 3759 | IQ8: =(IP8/IH8)*100 -> 0.2100575 | IR8: =IW8-IZ8 -> 1786812 | IS8: 108429 | IT8: 114886 | IU8: -6457 | IV8: =(IU8/IM8)*100 -> -0.36006868 | IW8: =JB8-JE8 -> 1793388 | IX8: 111381 | IY8: 104805 | IZ8: 6576 | JA8: =(IZ8/IR8)*100 -> 0.36802976 | JB8: =JG8-JJ8 -> 1813224 | JC8: 128126 | JD8: 108290 | JE8: 19836 | JF8: =(JE8/IW8)*100 -> 1.1060629 | JG8: =JL8-JO8 -> 1840353 | JH8: 116667 | JI8: 89538 | JJ8: 27129 | JK8: =(JJ8/JB8)*100 -> 1.4961748 | JL8: =JQ8-JT8 -> 1847041 | JM8: 103565 | JN8: 96877 | JO8: 6688 | JP8: =(JO8/JG8)*100 -> 0.36340854 | JQ8: =JV8-JY8 -> 1848442 | JR8: 97221 | JS8: 95820 | JT8: 1401 | JU8: =(JT8/JL8)*100 -> 0.07585105 | JV8: =KA8-KD8 -> 1846438 | JW8: 91557 | JX8: 93561 | JY8: -2004 | JZ8: =(JY8/JQ8)*100 -> -0.10841563 | KA8: =KF8-KI8 -> 1840681 | KB8: 95070 | KC8: 100827 | KD8: -5757 | KE8: =(KD8/JV8)*100 -> -0.31178951 | KF8: =KK8-KN8 -> 1821794 | KG8: 81144 | KH8: 100031 | KI8: -18887 | KJ8: =(KI8/KA8)*100 -> -1.0260876 | KK8: =KP8-KS8 -> 1775122 | KL8: 63185 | KM8: 109857 | KN8: -46672 | KO8: =(KN8/KF8)*100 -> -2.5618703 | KP8: =KU8-KX8 -> 1810876 | KQ8: 128372 | KR8: 92618 | KS8: 35754 | KT8: =(KS8/KK8)*100 -> 2.0141714 | KU8: =KZ8-LC8 -> 1830718 | KV8: 120205 | KW8: 100363 | KX8: 19842 | KY8: =(KX8/KP8)*100 -> 1.0957128 | KZ8: =LE8-LH8 -> 1825074 | LA8: 105093 | LB8: 110737 | LC8: -5644 | LD8: =(LC8/KU8)*100 -> -0.30829434 | LE8: =LJ8-LM8 -> 1829099 | LF8: 106109 | LG8: 102084 | LH8: 4025 | LI8: =(LH8/KZ8)*100 -> 0.220539 | LJ8: =LO8-LR8 -> 1846447 | LK8: 121825 | LL8: 104477 | LM8: 17348 | LN8: =(LM8/LE8)*100 -> 0.94844511 | LO8: =LT8-LW8 -> 1872280 | LP8: 115261 | LQ8: 89428 | LR8: 25833 | LS8: =(LR8/LJ8)*100 -> 1.3990653 | LT8: =LY8-MB8 -> 1881075 | LU8: 109024 | LV8: 100229 | LW8: 8795 | LX8: =(LW8/LO8)*100 -> 0.46974811 | LY8: =MD8-MG8 -> 1878410 | LZ8: 96454 | MA8: 99119 | MB8: -2665 | MC8: =(MB8/LT8)*100 -> -0.14167431 | MD8: =MI8-ML8 -> 1881577 | ME8: 96665 | MF8: 93498 | MG8: 3167 | MH8: =(MG8/LY8)*100 -> 0.16860004 | MI8: =MN8-MQ8 -> 1871660 | MJ8: 94411 | MK8: 104328 | ML8: -9917 | MM8: =(ML8/MD8)*100 -> -0.52705789 | MN8: =MS8-MV8 -> 1855094 | MO8: 77356 | MP8: 93922 | MQ8: -16566 | MR8: =(MQ8/MI8)*100 -> -0.88509665 | MS8: 1811258 | MT8: 63201 | MU8: 107037 | MV8: -43836 | MW8: =(MV8/MN8)*100 -> -2.3630069 | MX8: =MS8+NA8 -> 1834331 | MY8: 113385 | MZ8: 90312 | NA8: 23073 | NB8: 1.2550027 | NC8: =MX8+NF8 -> 1842454 | ND8: 111197 | NE8: 103074 | NF8: 8123 | NG8: =(NF8/NC8)*100 -> 0.44087939 | NH8: =NC8+NK8 -> 1824358 | NI8: 109101 | NJ8: 127197 | NK8: -18096 | NL8: =(NK8/NH8)*100 -> -0.99191058 | NM8: =NH8+NP8 -> 1815980 | NN8: 97242 | NO8: 105620 | NP8: -8378 | NQ8: -0.45871761 | NR8: =NM8+NU8 -> 1826185 | NS8: 115263 | NT8: 105058 | NU8: 10205 | NV8: 0.56134439 | NW8: =NR8+NZ8 -> 1849083 | NX8: 114801 | NY8: 91903 | NZ8: 22898 | OA8: 1.2517952 | OB8: =NW8+OE8 -> 1861606 | OC8: 110999 | OD8: 98476 | OE8: 12523 | OF8: 0.675881 | OG8: =SUM(ND8,MY8,NI8,NN8,NS8,NX8,OC8) -> 771988 | OH8: =SUM(NE8,MZ8,NJ8,NO8,NT8,NY8,OD8) -> 721640 | OI8: =SUM(NF8,NA8,NK8,NP8,NU8,NZ8,OE8) -> 50348 | OJ8: =(OI8/MS8)*100 -> 2.7797255 | OK8: =SUM(MT8,MO8,MJ8,ME8,LZ8,MY8,ND8,NI8,NN8,NS8,NX8,OC8) -> 1200075 | OL8: =SUM(MU8,MP8,MK8,MF8,MA8,MZ8,NE8,NJ8,NO8,NT8,NY8,OD8) -> 1219544 | OM8: =SUM(MV8,MQ8,ML8,MG8,MB8,NA8,NF8,NK8,NP8,NU8,NZ8,OE8) -> -19469 | ON8: =OM8/(OB8-OM8)*100 -> -1.0349933
B9: Indústria geral | C9: =G9-J9 -> 7614408 | D9: 240766 | E9: 184933 | F9: 55833 | G9: =L9-O9 -> 7650640 | H9: 250477 | I9: 214245 | J9: 36232 | K9: =(J9/C9)*100 -> 0.47583476 | L9: =Q9-T9 -> 7616899 | M9: 225973 | N9: 259714 | O9: -33741 | P9: =(O9/G9)*100 -> -0.44102193 | Q9: =V9-Y9 -> 7411821 | R9: 96258 | S9: 301336 | T9: -205078 | U9: =(T9/L9)*100 -> -2.692408 | V9: =AA9-AD9 -> 7311156 | W9: 102957 | X9: 203622 | Y9: -100665 | Z9: =(Y9/Q9)*100 -> -1.3581683 | AA9: =AF9-AI9 -> 7305639 | AB9: 145974 | AC9: 151491 | AD9: -5517 | AE9: =(AD9/V9)*100 -> -0.075460023 | AF9: =AK9-AN9 -> 7358270 | AG9: 207798 | AH9: 155167 | AI9: 52631 | AJ9: =(AI9/AA9)*100 -> 0.72041611 | AK9: =AP9-AS9 -> 7451103 | AL9: 256386 | AM9: 163553 | AN9: 92833 | AO9: =(AN9/AF9)*100 -> 1.2616145 | AP9: =AU9-AX9 -> 7561803 | AQ9: 295576 | AR9: 184876 | AS9: 110700 | AT9: =(AS9/AK9)*100 -> 1.4856861 | AU9: =AZ9-BC9 -> 7647586 | AV9: 286999 | AW9: 201216 | AX9: 85783 | AY9: =(AX9/AP9)*100 -> 1.1344252 | AZ9: =BE9-BH9 -> 7698099 | BA9: 253408 | BB9: 202895 | BC9: 50513 | BD9: =(BC9/AU9)*100 -> 0.66050908 | BE9: =BJ9-BM9 -> 7655197 | BF9: 174451 | BG9: 217353 | BH9: -42902 | BI9: =(BH9/AZ9)*100 -> -0.55730642 | BJ9: =BO9-BR9 -> 7745433 | BK9: 296040 | BL9: 205804 | BM9: 90236 | BN9: =(BM9/BE9)*100 -> 1.1787548 | BO9: =BT9-BW9 -> 7838432 | BP9: 322289 | BQ9: 229290 | BR9: 92999 | BS9: =(BR9/BJ9)*100 -> 1.2006947 | BT9: =BY9-CB9 -> 7879224 | BU9: 294054 | BV9: 253262 | BW9: 40792 | BX9: =(BW9/BO9)*100 -> 0.5204102 | BY9: =CD9-CG9 -> 7897864 | BZ9: 243008 | CA9: 224368 | CB9: 18640 | CC9: =(CB9/BT9)*100 -> 0.23657152 | CD9: =CI9-CL9 -> 7941627 | CE9: 258154 | CF9: 214391 | CG9: 43763 | CH9: =(CG9/BY9)*100 -> 0.55411185 | CI9: =CN9-CQ9 -> 7991749 | CJ9: 262080 | CK9: 211958 | CL9: 50122 | CM9: =(CL9/CD9)*100 -> 0.63113012 | CN9: =CS9-CV9 -> 8050579 | CO9: 278431 | CP9: 219601 | CQ9: 58830 | CR9: =(CQ9/CI9)*100 -> 0.73613423 | CS9: =CX9-DA9 -> 8123341 | CT9: 310814 | CU9: 238052 | CV9: 72762 | CW9: =(CV9/CN9)*100 -> 0.90381077 | CX9: =DC9-DF9 -> 8199536 | CY9: 310478 | CZ9: 234283 | DA9: 76195 | DB9: =(DA9/CS9)*100 -> 0.93797614 | DC9: =DH9-DK9 -> 8226233 | DD9: 270604 | DE9: 243907 | DF9: 26697 | DG9: =(DF9/CX9)*100 -> 0.32559159 | DH9: =DM9-DP9 -> 8234410 | DI9: 243191 | DJ9: 235014 | DK9: 8177 | DL9: =(DK9/DC9)*100 -> 0.099401512 | DM9: =DR9-DU9 -> 8142363 | DN9: 166083 | DO9: 258130 | DP9: -92047 | DQ9: =(DP9/DH9)*100 -> -1.1178336 | DR9: =DW9-DZ9 -> 8193782 | DS9: 284673 | DT9: 233254 | DU9: 51419 | DV9: =(DU9/DM9)*100 -> 0.63149973 | DW9: =EB9-EE9 -> 8236782 | DX9: 312833 | DY9: 269833 | DZ9: 43000 | EA9: =(DZ9/DR9)*100 -> 0.52478819 | EB9: =EG9-EJ9 -> 8252042 | EC9: 309012 | ED9: 293752 | EE9: 15260 | EF9: =(EE9/DW9)*100 -> 0.18526653 | EG9: =EL9-EO9 -> 8278420 | EH9: 285885 | EI9: 259507 | EJ9: 26378 | EK9: =(EJ9/EB9)*100 -> 0.31965421 | EL9: =EQ9-ET9 -> 8325395 | EM9: 308939 | EN9: 261964 | EO9: 46975 | EP9: =(EO9/EG9)*100 -> 0.5674392 | EQ9: =EV9-EY9 -> 8366912 | ER9: 293330 | ES9: 251813 | ET9: 41517 | EU9: =(ET9/EL9)*100 -> 0.49867904 | EV9: =FA9-FD9 -> 8417415 | EW9: 303323 | EX9: 252820 | EY9: 50503 | EZ9: =(EY9/EQ9)*100 -> 0.60360381 | FA9: =FF9-FI9 -> 8470175 | FB9: 324438 | FC9: 271678 | FD9: 52760 | FE9: =(FD9/EV9)*100 -> 0.62679576 | FF9: =FK9-FN9 -> 8527084 | FG9: 306362 | FH9: 249453 | FI9: 56909 | FJ9: =(FI9/FA9)*100 -> 0.67187514 | FK9: =FP9-FS9 -> 8541975 | FL9: 263318 | FM9: 248427 | FN9: 14891 | FO9: =(FN9/FF9)*100 -> 0.1746318 | FP9: =FU9-FX9 -> 8516268 | FQ9: 229430 | FR9: 255137 | FS9: -25707 | FT9: =(FS9/FK9)*100 -> -0.30094914 | FU9: =FZ9-GC9 -> 8402022 | FV9: 156219 | FW9: 270465 | FX9: -114246 | FY9: =(FX9/FP9)*100 -> -1.3415031 | FZ9: =GE9-GH9 -> 8436045 | GA9: 296574 | GB9: 262551 | GC9: 34023 | GD9: =(GC9/FU9)*100 -> 0.40493824 | GE9: =GJ9-GM9 -> 8476425 | GF9: 305814 | GG9: 265434 | GH9: 40380 | GI9: =(GH9/FZ9)*100 -> 0.47866032 | GJ9: =GO9-GR9 -> 8497409 | GK9: 334970 | GL9: 313986 | GM9: 20984 | GN9: =(GM9/GE9)*100 -> 0.2475572 | GO9: =GT9-GW9 -> 8516122 | GP9: 291273 | GQ9: 272560 | GR9: 18713 | GS9: =(GR9/GJ9)*100 -> 0.22022007 | GT9: =GY9-HB9 -> 8524551 | GU9: 305955 | GV9: 297526 | GW9: 8429 | GX9: =(GW9/GO9)*100 -> 0.098976976 | GY9: =HD9-HG9 -> 8536668 | GZ9: 288512 | HA9: 276395 | HB9: 12117 | HC9: =(HB9/GT9)*100 -> 0.14214238 | HD9: =HI9-HL9 -> 8557922 | HE9: 291362 | HF9: 270108 | HG9: 21254 | HH9: =(HG9/GY9)*100 -> 0.24897302 | HI9: =HN9-HQ9 -> 8589008 | HJ9: 327861 | HK9: 296775 | HL9: 31086 | HM9: =(HL9/HD9)*100 -> 0.36324239 | HN9: =HS9-HV9 -> 8632222 | HO9: 301495 | HP9: 258281 | HQ9: 43214 | HR9: =(HQ9/HI9)*100 -> 0.50313144 | HS9: =HX9-IA9 -> 8653176 | HT9: 285880 | HU9: 264926 | HV9: 20954 | HW9: =(HV9/HN9)*100 -> 0.24274167 | HX9: =IC9-IF9 -> 8640265 | HY9: 250561 | HZ9: 263472 | IA9: -12911 | IB9: =(IA9/HS9)*100 -> -0.14920533 | IC9: =IH9-IK9 -> 8529259 | ID9: 173547 | IE9: 284553 | IF9: -111006 | IG9: =(IF9/HX9)*100 -> -1.2847523 | IH9: =IM9-IP9 -> 8596288 | II9: 336020 | IJ9: 268991 | IK9: 67029 | IL9: =(IK9/IC9)*100 -> 0.78587132 | IM9: =IR9-IU9 -> 8650736 | IN9: 352923 | IO9: 298475 | IP9: 54448 | IQ9: =(IP9/IH9)*100 -> 0.63338967 | IR9: =IW9-IZ9 -> 8686622 | IS9: 351011 | IT9: 315125 | IU9: 35886 | IV9: =(IU9/IM9)*100 -> 0.41483176 | IW9: =JB9-JE9 -> 8722612 | IX9: 361885 | IY9: 325895 | IZ9: 35990 | JA9: =(IZ9/IR9)*100 -> 0.41431525 | JB9: =JG9-JJ9 -> 8740757 | JC9: 321202 | JD9: 303057 | JE9: 18145 | JF9: =(JE9/IW9)*100 -> 0.20802255 | JG9: =JL9-JO9 -> 8772780 | JH9: 320466 | JI9: 288443 | JJ9: 32023 | JK9: =(JJ9/JB9)*100 -> 0.36636415 | JL9: =JQ9-JT9 -> 8822251 | JM9: 355721 | JN9: 306250 | JO9: 49471 | JP9: =(JO9/JG9)*100 -> 0.56391475 | JQ9: =JV9-JY9 -> 8873885 | JR9: 362966 | JS9: 311332 | JT9: 51634 | JU9: =(JT9/JL9)*100 -> 0.58527013 | JV9: =KA9-KD9 -> 8933712 | JW9: 350899 | JX9: 291072 | JY9: 59827 | JZ9: =(JY9/JQ9)*100 -> 0.67419174 | KA9: =KF9-KI9 -> 8957441 | KB9: 344779 | KC9: 321050 | KD9: 23729 | KE9: =(KD9/JV9)*100 -> 0.26561188 | KF9: =KK9-KN9 -> 8950763 | KG9: 276702 | KH9: 283380 | KI9: -6678 | KJ9: =(KI9/KA9)*100 -> -0.074552542 | KK9: =KP9-KS9 -> 8834341 | KL9: 176461 | KM9: 292883 | KN9: -116422 | KO9: =(KN9/KF9)*100 -> -1.3006936 | KP9: =KU9-KX9 -> 8904769 | KQ9: 376449 | KR9: 306021 | KS9: 70428 | KT9: =(KS9/KK9)*100 -> 0.79720717 | KU9: =KZ9-LC9 -> 8974653 | KV9: 407183 | KW9: 337299 | KX9: 69884 | KY9: =(KX9/KP9)*100 -> 0.78479296 | KZ9: =LE9-LH9 -> 8987784 | LA9: 353960 | LB9: 340829 | LC9: 13131 | LD9: =(LC9/KU9)*100 -> 0.14631206 | LE9: =LJ9-LM9 -> 9022852 | LF9: 360591 | LG9: 325523 | LH9: 35068 | LI9: =(LH9/KZ9)*100 -> 0.39017404 | LJ9: =LO9-LR9 -> 9044421 | LK9: 344875 | LL9: 323306 | LM9: 21569 | LN9: =(LM9/LE9)*100 -> 0.23904858 | LO9: =LT9-LW9 -> 9064526 | LP9: 326689 | LQ9: 306584 | LR9: 20105 | LS9: =(LR9/LJ9)*100 -> 0.22229173 | LT9: =LY9-MB9 -> 9088952 | LU9: 353542 | LV9: 329116 | LW9: 24426 | LX9: =(LW9/LO9)*100 -> 0.26946803 | LY9: =MD9-MG9 -> 9108050 | LZ9: 342784 | MA9: 323686 | MB9: 19098 | MC9: =(MB9/LT9)*100 -> 0.21012324 | MD9: =MI9-ML9 -> 9151145 | ME9: 359669 | MF9: 316574 | MG9: 43095 | MH9: =(MG9/LY9)*100 -> 0.47315287 | MI9: =MN9-MQ9 -> 9141053 | MJ9: 326980 | MK9: 337072 | ML9: -10092 | MM9: =(ML9/MD9)*100 -> -0.11028128 | MN9: =MS9-MV9 -> 9113918 | MO9: 263122 | MP9: 290257 | MQ9: -27135 | MR9: =(MQ9/MI9)*100 -> -0.29684764 | MS9: 8978831 | MT9: 167306 | MU9: 302393 | MV9: -135087 | MW9: =(MV9/MN9)*100 -> -1.4822056 | MX9: =MS9+NA9 -> 9033822 | MY9: 353793 | MZ9: 298802 | NA9: 54991 | NB9: 0.60631096 | NC9: =MX9+NF9 -> 9065849 | ND9: 358595 | NE9: 326568 | NF9: 32027 | NG9: =(NF9/NC9)*100 -> 0.35327083 | NH9: =NC9+NK9 -> 9094185 | NI9: 386664 | NJ9: 358328 | NK9: 28336 | NL9: =(NK9/NH9)*100 -> 0.31158372 | NM9: =NH9+NP9 -> 9103441 | NN9: 349222 | NO9: 339966 | NP9: 9256 | NQ9: 0.1017852 | NR9: =NM9+NU9 -> 9108415 | NS9: 329882 | NT9: 324908 | NU9: 4974 | NV9: 0.054646071 | NW9: =NR9+NZ9 -> 9122853 | NX9: 331149 | NY9: 316711 | NZ9: 14438 | OA9: 0.15852286 | OB9: =NW9+OE9 -> 9134168 | OC9: 344080 | OD9: 332765 | OE9: 11315 | OF9: 0.124047 | OG9: =SUM(ND9,MY9,NI9,NN9,NS9,NX9,OC9) -> 2453385 | OH9: =SUM(NE9,MZ9,NJ9,NO9,NT9,NY9,OD9) -> 2298048 | OI9: =SUM(NF9,NA9,NK9,NP9,NU9,NZ9,OE9) -> 155337 | OJ9: =(OI9/MS9)*100 -> 1.7300359 | OK9: =SUM(MT9,MO9,MJ9,ME9,LZ9,MY9,ND9,NI9,NN9,NS9,NX9,OC9) -> 3913246 | OL9: =SUM(MU9,MP9,MK9,MF9,MA9,MZ9,NE9,NJ9,NO9,NT9,NY9,OD9) -> 3868030 | OM9: =SUM(MV9,MQ9,ML9,MG9,MB9,NA9,NF9,NK9,NP9,NU9,NZ9,OE9) -> 45216 | ON9: =OM9/(OB9-OM9)*100 -> 0.4974831
B10: Indústrias Extrativas | C10: =G10-J10 -> 218769 | D10: 3284 | E10: 3127 | F10: 157 | G10: =L10-O10 -> 220108 | H10: 4463 | I10: 3124 | J10: 1339 | K10: =(J10/C10)*100 -> 0.61206112 | L10: =Q10-T10 -> 219915 | M10: 3685 | N10: 3878 | O10: -193 | P10: =(O10/G10)*100 -> -0.087684228 | Q10: =V10-Y10 -> 218629 | R10: 2063 | S10: 3349 | T10: -1286 | U10: =(T10/L10)*100 -> -0.58477139 | V10: =AA10-AD10 -> 218085 | W10: 2598 | X10: 3142 | Y10: -544 | Z10: =(Y10/Q10)*100 -> -0.24882335 | AA10: =AF10-AI10 -> 218721 | AB10: 3563 | AC10: 2927 | AD10: 636 | AE10: =(AD10/V10)*100 -> 0.29162941 | AF10: =AK10-AN10 -> 219612 | AG10: 4062 | AH10: 3171 | AI10: 891 | AJ10: =(AI10/AA10)*100 -> 0.40736829 | AK10: =AP10-AS10 -> 220486 | AL10: 4400 | AM10: 3526 | AN10: 874 | AO10: =(AN10/AF10)*100 -> 0.39797461 | AP10: =AU10-AX10 -> 221383 | AQ10: 4611 | AR10: 3714 | AS10: 897 | AT10: =(AS10/AK10)*100 -> 0.40682855 | AU10: =AZ10-BC10 -> 222603 | AV10: 4682 | AW10: 3462 | AX10: 1220 | AY10: =(AX10/AP10)*100 -> 0.55108116 | AZ10: =BE10-BH10 -> 223683 | BA10: 4383 | BB10: 3303 | BC10: 1080 | BD10: =(BC10/AU10)*100 -> 0.48516866 | BE10: =BJ10-BM10 -> 223142 | BF10: 3405 | BG10: 3946 | BH10: -541 | BI10: =(BH10/AZ10)*100 -> -0.24186013 | BJ10: =BO10-BR10 -> 224626 | BK10: 4711 | BL10: 3227 | BM10: 1484 | BN10: =(BM10/BE10)*100 -> 0.66504737 | BO10: =BT10-BW10 -> 226974 | BP10: 5560 | BQ10: 3212 | BR10: 2348 | BS10: =(BR10/BJ10)*100 -> 1.0452931 | BT10: =BY10-CB10 -> 228380 | BU10: 5477 | BV10: 4071 | BW10: 1406 | BX10: =(BW10/BO10)*100 -> 0.61945421 | BY10: =CD10-CG10 -> 230748 | BZ10: 5715 | CA10: 3347 | CB10: 2368 | CC10: =(CB10/BT10)*100 -> 1.0368684 | CD10: =CI10-CL10 -> 233298 | CE10: 6209 | CF10: 3659 | CG10: 2550 | CH10: =(CG10/BY10)*100 -> 1.1051017 | CI10: =CN10-CQ10 -> 235537 | CJ10: 5903 | CK10: 3664 | CL10: 2239 | CM10: =(CL10/CD10)*100 -> 0.95971676 | CN10: =CS10-CV10 -> 237671 | CO10: 6080 | CP10: 3946 | CQ10: 2134 | CR10: =(CQ10/CI10)*100 -> 0.90601477 | CS10: =CX10-DA10 -> 239352 | CT10: 5921 | CU10: 4240 | CV10: 1681 | CW10: =(CV10/CN10)*100 -> 0.70728023 | CX10: =DC10-DF10 -> 241020 | CY10: 5947 | CZ10: 4279 | DA10: 1668 | DB10: =(DA10/CS10)*100 -> 0.69688158 | DC10: =DH10-DK10 -> 242171 | DD10: 5326 | DE10: 4175 | DF10: 1151 | DG10: =(DF10/CX10)*100 -> 0.47755373 | DH10: =DM10-DP10 -> 242630 | DI10: 4588 | DJ10: 4129 | DK10: 459 | DL10: =(DK10/DC10)*100 -> 0.18953549 | DM10: =DR10-DU10 -> 241505 | DN10: 3628 | DO10: 4753 | DP10: -1125 | DQ10: =(DP10/DH10)*100 -> -0.46366896 | DR10: =DW10-DZ10 -> 242012 | DS10: 4481 | DT10: 3974 | DU10: 507 | DV10: =(DU10/DM10)*100 -> 0.20993354 | DW10: =EB10-EE10 -> 243916 | DX10: 6167 | DY10: 4263 | DZ10: 1904 | EA10: =(DZ10/DR10)*100 -> 0.78673785 | EB10: =EG10-EJ10 -> 244807 | EC10: 5492 | ED10: 4601 | EE10: 891 | EF10: =(EE10/DW10)*100 -> 0.36528969 | EG10: =EL10-EO10 -> 246298 | EH10: 5767 | EI10: 4276 | EJ10: 1491 | EK10: =(EJ10/EB10)*100 -> 0.60905121 | EL10: =EQ10-ET10 -> 247819 | EM10: 6098 | EN10: 4577 | EO10: 1521 | EP10: =(EO10/EG10)*100 -> 0.6175446 | EQ10: =EV10-EY10 -> 249156 | ER10: 5673 | ES10: 4336 | ET10: 1337 | EU10: =(ET10/EL10)*100 -> 0.53950666 | EV10: =FA10-FD10 -> 250727 | EW10: 5960 | EX10: 4389 | EY10: 1571 | EZ10: =(EY10/EQ10)*100 -> 0.63052866 | FA10: =FF10-FI10 -> 251957 | FB10: 6202 | FC10: 4972 | FD10: 1230 | FE10: =(FD10/EV10)*100 -> 0.49057341 | FF10: =FK10-FN10 -> 253076 | FG10: 5899 | FH10: 4780 | FI10: 1119 | FJ10: =(FI10/FA10)*100 -> 0.4441234 | FK10: =FP10-FS10 -> 253761 | FL10: 5817 | FM10: 5132 | FN10: 685 | FO10: =(FN10/FF10)*100 -> 0.27066968 | FP10: =FU10-FX10 -> 254665 | FQ10: 5644 | FR10: 4740 | FS10: 904 | FT10: =(FS10/FK10)*100 -> 0.35624071 | FU10: =FZ10-GC10 -> 254327 | FV10: 4145 | FW10: 4483 | FX10: -338 | FY10: =(FX10/FP10)*100 -> -0.13272338 | FZ10: =GE10-GH10 -> 254668 | GA10: 5157 | GB10: 4816 | GC10: 341 | GD10: =(GC10/FU10)*100 -> 0.13407935 | GE10: =GJ10-GM10 -> 255993 | GF10: 5802 | GG10: 4477 | GH10: 1325 | GI10: =(GH10/FZ10)*100 -> 0.52028523 | GJ10: =GO10-GR10 -> 257559 | GK10: 6720 | GL10: 5154 | GM10: 1566 | GN10: =(GM10/GE10)*100 -> 0.61173548 | GO10: =GT10-GW10 -> 260034 | GP10: 6933 | GQ10: 4458 | GR10: 2475 | GS10: =(GR10/GJ10)*100 -> 0.96094487 | GT10: =GY10-HB10 -> 262678 | GU10: 7583 | GV10: 4939 | GW10: 2644 | GX10: =(GW10/GO10)*100 -> 1.0167901 | GY10: =HD10-HG10 -> 264503 | GZ10: 7131 | HA10: 5306 | HB10: 1825 | HC10: =(HB10/GT10)*100 -> 0.69476698 | HD10: =HI10-HL10 -> 265718 | HE10: 6317 | HF10: 5102 | HG10: 1215 | HH10: =(HG10/GY10)*100 -> 0.45935207 | HI10: =HN10-HQ10 -> 266784 | HJ10: 6563 | HK10: 5497 | HL10: 1066 | HM10: =(HL10/HD10)*100 -> 0.40117719 | HN10: =HS10-HV10 -> 267866 | HO10: 6115 | HP10: 5033 | HQ10: 1082 | HR10: =(HQ10/HI10)*100 -> 0.40557155 | HS10: =HX10-IA10 -> 268974 | HT10: 5745 | HU10: 4637 | HV10: 1108 | HW10: =(HV10/HN10)*100 -> 0.41363966 | HX10: =IC10-IF10 -> 269258 | HY10: 4995 | HZ10: 4711 | IA10: 284 | IB10: =(IA10/HS10)*100 -> 0.10558641 | IC10: =IH10-IK10 -> 268823 | ID10: 3935 | IE10: 4370 | IF10: -435 | IG10: =(IF10/HX10)*100 -> -0.16155509 | IH10: =IM10-IP10 -> 269298 | II10: 5596 | IJ10: 5121 | IK10: 475 | IL10: =(IK10/IC10)*100 -> 0.17669619 | IM10: =IR10-IU10 -> 270556 | IN10: 6401 | IO10: 5143 | IP10: 1258 | IQ10: =(IP10/IH10)*100 -> 0.46714049 | IR10: =IW10-IZ10 -> 271419 | IS10: 6285 | IT10: 5422 | IU10: 863 | IV10: =(IU10/IM10)*100 -> 0.31897278 | IW10: =JB10-JE10 -> 273306 | IX10: 7130 | IY10: 5243 | IZ10: 1887 | JA10: =(IZ10/IR10)*100 -> 0.69523504 | JB10: =JG10-JJ10 -> 275300 | JC10: 7044 | JD10: 5050 | JE10: 1994 | JF10: =(JE10/IW10)*100 -> 0.72958515 | JG10: =JL10-JO10 -> 276957 | JH10: 6717 | JI10: 5060 | JJ10: 1657 | JK10: =(JJ10/JB10)*100 -> 0.60188885 | JL10: =JQ10-JT10 -> 278199 | JM10: 6909 | JN10: 5667 | JO10: 1242 | JP10: =(JO10/JG10)*100 -> 0.44844507 | JQ10: =JV10-JY10 -> 279745 | JR10: 6798 | JS10: 5252 | JT10: 1546 | JU10: =(JT10/JL10)*100 -> 0.55571731 | JV10: =KA10-KD10 -> 280926 | JW10: 6417 | JX10: 5236 | JY10: 1181 | JZ10: =(JY10/JQ10)*100 -> 0.42217019 | KA10: =KF10-KI10 -> 281008 | KB10: 5969 | KC10: 5887 | KD10: 82 | KE10: =(KD10/JV10)*100 -> 0.029189181 | KF10: =KK10-KN10 -> 281240 | KG10: 5672 | KH10: 5440 | KI10: 232 | KJ10: =(KI10/KA10)*100 -> 0.082559927 | KK10: =KP10-KS10 -> 280407 | KL10: 4174 | KM10: 5007 | KN10: -833 | KO10: =(KN10/KF10)*100 -> -0.29618831 | KP10: =KU10-KX10 -> 281007 | KQ10: 6059 | KR10: 5459 | KS10: 600 | KT10: =(KS10/KK10)*100 -> 0.21397469 | KU10: =KZ10-LC10 -> 282741 | KV10: 7245 | KW10: 5511 | KX10: 1734 | KY10: =(KX10/KP10)*100 -> 0.61706648 | KZ10: =LE10-LH10 -> 283196 | LA10: 6026 | LB10: 5571 | LC10: 455 | LD10: =(LC10/KU10)*100 -> 0.16092466 | LE10: =LJ10-LM10 -> 284206 | LF10: 6292 | LG10: 5282 | LH10: 1010 | LI10: =(LH10/KZ10)*100 -> 0.35664346 | LJ10: =LO10-LR10 -> 285520 | LK10: 6799 | LL10: 5485 | LM10: 1314 | LN10: =(LM10/LE10)*100 -> 0.4623407 | LO10: =LT10-LW10 -> 286577 | LP10: 6317 | LQ10: 5260 | LR10: 1057 | LS10: =(LR10/LJ10)*100 -> 0.37020174 | LT10: =LY10-MB10 -> 288363 | LU10: 7249 | LV10: 5463 | LW10: 1786 | LX10: =(LW10/LO10)*100 -> 0.62321819 | LY10: =MD10-MG10 -> 288860 | LZ10: 6377 | MA10: 5880 | MB10: 497 | MC10: =(MB10/LT10)*100 -> 0.17235221 | MD10: =MI10-ML10 -> 289701 | ME10: 6626 | MF10: 5785 | MG10: 841 | MH10: =(MG10/LY10)*100 -> 0.2911445 | MI10: =MN10-MQ10 -> 290483 | MJ10: 6627 | MK10: 5845 | ML10: 782 | MM10: =(ML10/MD10)*100 -> 0.26993348 | MN10: =MS10-MV10 -> 290786 | MO10: 5668 | MP10: 5365 | MQ10: 303 | MR10: =(MQ10/MI10)*100 -> 0.10430903 | MS10: 289917 | MT10: 4497 | MU10: 5366 | MV10: -869 | MW10: =(MV10/MN10)*100 -> -0.2988452 | MX10: =MS10+NA10 -> 290358 | MY10: 5786 | MZ10: 5345 | NA10: 441 | NB10: 0.15114334 | NC10: =MX10+NF10 -> 291557 | ND10: 6297 | NE10: 5098 | NF10: 1199 | NG10: =(NF10/NC10)*100 -> 0.41124034 | NH10: =NC10+NK10 -> 293243 | NI10: 7284 | NJ10: 5598 | NK10: 1686 | NL10: =(NK10/NH10)*100 -> 0.57494979 | NM10: =NH10+NP10 -> 293829 | NN10: 6270 | NO10: 5684 | NP10: 586 | NQ10: 0.19990107 | NR10: =NM10+NU10 -> 294251 | NS10: 5839 | NT10: 5417 | NU10: 422 | NV10: 0.14369185 | NW10: =NR10+NZ10 -> 294433 | NX10: 5698 | NY10: 5516 | NZ10: 182 | OA10: 0.061874878 | OB10: =NW10+OE10 -> 294451 | OC10: 5786 | OD10: 5768 | OE10: 18 | OF10: 0.006117 | OG10: =SUM(ND10,MY10,NI10,NN10,NS10,NX10,OC10) -> 42960 | OH10: =SUM(NE10,MZ10,NJ10,NO10,NT10,NY10,OD10) -> 38426 | OI10: =SUM(NF10,NA10,NK10,NP10,NU10,NZ10,OE10) -> 4534 | OJ10: =(OI10/MS10)*100 -> 1.5638959 | OK10: =SUM(MT10,MO10,MJ10,ME10,LZ10,MY10,ND10,NI10,NN10,NS10,NX10,OC10) -> 72755 | OL10: =SUM(MU10,MP10,MK10,MF10,MA10,MZ10,NE10,NJ10,NO10,NT10,NY10,OD10) -> 66667 | OM10: =SUM(MV10,MQ10,ML10,MG10,MB10,NA10,NF10,NK10,NP10,NU10,NZ10,OE10) -> 6088 | ON10: =OM10/(OB10-OM10)*100 -> 2.1112279
